(llava) guoyunfei@tme-GS4840:~/projects/LLaVA-main/llava$ TRANSFORMERS_OFFLINE=1 HF_HUB_OFFLINE=1 . finetune.sh 
[2024-08-16 16:14:43,545] [INFO] [real_accelerator.py:161:get_accelerator] Setting ds_accelerator to cuda (auto detect)
[2024-08-16 16:14:45,577] [WARNING] [runner.py:202:fetch_hostfile] Unable to find hostfile, will proceed with training with local resources only.
[2024-08-16 16:14:45,577] [INFO] [runner.py:571:main] cmd = /home/guoyunfei/.conda/envs/llava/bin/python -u -m deepspeed.launcher.launch --world_info=eyJsb2NhbGhvc3QiOiBbMCwgMSwgMiwgMywgNCwgNSwgNiwgN119 --master_addr=127.0.0.1 --master_port=29500 --enable_each_rank_log=None /home/guoyunfei/projects/LLaVA-main/llava/train/train_mem.py --deepspeed /home/guoyunfei/projects/LLaVA-main/scripts/zero2.json --model_name_or_path /data0/GYF/offline_model/liuhaotian/llava-v1.6-mistral-7b --version plain --data_path /data0/GYF/data/llava-med/data/Instruction-Tuning/llava_med_instruct_60k_inline_mention2024081602.json --image_folder /data0/GYF/data/llava-med/images --vision_tower /data0/GYF/offline_model/openai/clip-vit-large-patch14 --pretrain_mm_mlp_adapter ./checkpoints/llava-v1.6-7b-13GB-pretrain/mm_projector.bin --mm_vision_select_layer -2 --mm_use_im_start_end False --mm_use_im_patch_token False --bf16 True --output_dir ./checkpoints/llava-v1.6-7b_plain-finetune --num_train_epochs 1 --per_device_train_batch_size 16 --per_device_eval_batch_size 4 --gradient_accumulation_steps 1 --evaluation_strategy no --save_strategy steps --save_steps 50000 --save_total_limit 1 --learning_rate 2e-5 --weight_decay 0. --warmup_ratio 0.03 --lr_scheduler_type cosine --logging_steps 1 --tf32 True --model_max_length 2048 --gradient_checkpointing True --dataloader_num_workers 4 --lazy_preprocess True --report_to wandb
[2024-08-16 16:14:47,688] [INFO] [real_accelerator.py:161:get_accelerator] Setting ds_accelerator to cuda (auto detect)
[2024-08-16 16:14:49,253] [INFO] [launch.py:145:main] WORLD INFO DICT: {'localhost': [0, 1, 2, 3, 4, 5, 6, 7]}
[2024-08-16 16:14:49,253] [INFO] [launch.py:151:main] nnodes=1, num_local_procs=8, node_rank=0
[2024-08-16 16:14:49,253] [INFO] [launch.py:162:main] global_rank_mapping=defaultdict(<class 'list'>, {'localhost': [0, 1, 2, 3, 4, 5, 6, 7]})
[2024-08-16 16:14:49,253] [INFO] [launch.py:163:main] dist_world_size=8
[2024-08-16 16:14:49,253] [INFO] [launch.py:165:main] Setting CUDA_VISIBLE_DEVICES=0,1,2,3,4,5,6,7
[2024-08-16 16:14:52,848] [INFO] [real_accelerator.py:161:get_accelerator] Setting ds_accelerator to cuda (auto detect)
[2024-08-16 16:14:53,140] [INFO] [real_accelerator.py:161:get_accelerator] Setting ds_accelerator to cuda (auto detect)
[2024-08-16 16:14:53,289] [INFO] [real_accelerator.py:161:get_accelerator] Setting ds_accelerator to cuda (auto detect)
[2024-08-16 16:14:53,790] [INFO] [real_accelerator.py:161:get_accelerator] Setting ds_accelerator to cuda (auto detect)
[2024-08-16 16:14:53,876] [INFO] [real_accelerator.py:161:get_accelerator] Setting ds_accelerator to cuda (auto detect)
[2024-08-16 16:14:53,949] [INFO] [comm.py:637:init_distributed] cdb=None
[2024-08-16 16:14:54,213] [INFO] [real_accelerator.py:161:get_accelerator] Setting ds_accelerator to cuda (auto detect)
[2024-08-16 16:14:54,213] [INFO] [real_accelerator.py:161:get_accelerator] Setting ds_accelerator to cuda (auto detect)
[2024-08-16 16:14:54,244] [INFO] [real_accelerator.py:161:get_accelerator] Setting ds_accelerator to cuda (auto detect)
[2024-08-16 16:14:54,286] [INFO] [comm.py:637:init_distributed] cdb=None
[2024-08-16 16:14:54,466] [INFO] [comm.py:637:init_distributed] cdb=None
[2024-08-16 16:14:54,894] [INFO] [comm.py:637:init_distributed] cdb=None
[2024-08-16 16:14:55,431] [INFO] [comm.py:637:init_distributed] cdb=None
[2024-08-16 16:14:55,432] [INFO] [comm.py:668:init_distributed] Initializing TorchBackend in DeepSpeed with backend nccl
[2024-08-16 16:14:55,497] [INFO] [comm.py:637:init_distributed] cdb=None
[2024-08-16 16:14:55,552] [INFO] [comm.py:637:init_distributed] cdb=None
[2024-08-16 16:14:55,552] [INFO] [comm.py:637:init_distributed] cdb=None
You are using a model of type llava_mistral to instantiate a model of type llava_llama. This is not supported for all configurations of models and can yield errors.
You are using a model of type llava_mistral to instantiate a model of type llava_llama. This is not supported for all configurations of models and can yield errors.
You are attempting to use Flash Attention 2.0 with a model not initialized on GPU. Make sure to move the model to GPU after initializing it on CPU with `model.to('cuda')`.
You are attempting to use Flash Attention 2.0 with a model not initialized on GPU. Make sure to move the model to GPU after initializing it on CPU with `model.to('cuda')`.
You are using a model of type llava_mistral to instantiate a model of type llava_llama. This is not supported for all configurations of models and can yield errors.
You are attempting to use Flash Attention 2.0 with a model not initialized on GPU. Make sure to move the model to GPU after initializing it on CPU with `model.to('cuda')`.
You are using a model of type llava_mistral to instantiate a model of type llava_llama. This is not supported for all configurations of models and can yield errors.
You are attempting to use Flash Attention 2.0 with a model not initialized on GPU. Make sure to move the model to GPU after initializing it on CPU with `model.to('cuda')`.
You are using a model of type llava_mistral to instantiate a model of type llava_llama. This is not supported for all configurations of models and can yield errors.
You are attempting to use Flash Attention 2.0 with a model not initialized on GPU. Make sure to move the model to GPU after initializing it on CPU with `model.to('cuda')`.
You are using a model of type llava_mistral to instantiate a model of type llava_llama. This is not supported for all configurations of models and can yield errors.
You are attempting to use Flash Attention 2.0 with a model not initialized on GPU. Make sure to move the model to GPU after initializing it on CPU with `model.to('cuda')`.
You are using a model of type llava_mistral to instantiate a model of type llava_llama. This is not supported for all configurations of models and can yield errors.
You are attempting to use Flash Attention 2.0 with a model not initialized on GPU. Make sure to move the model to GPU after initializing it on CPU with `model.to('cuda')`.
You are using a model of type llava_mistral to instantiate a model of type llava_llama. This is not supported for all configurations of models and can yield errors.
You are attempting to use Flash Attention 2.0 with a model not initialized on GPU. Make sure to move the model to GPU after initializing it on CPU with `model.to('cuda')`.
/home/guoyunfei/.conda/envs/llava/lib/python3.10/site-packages/torch/_utils.py:831: UserWarning: TypedStorage is deprecated. It will be removed in the future and UntypedStorage will be the only storage class. This should only matter to you if you are using storages directly.  To access UntypedStorage directly, use tensor.untyped_storage() instead of tensor.storage()
  return self.fget.__get__(instance, owner)()
/home/guoyunfei/.conda/envs/llava/lib/python3.10/site-packages/torch/_utils.py:831: UserWarning: TypedStorage is deprecated. It will be removed in the future and UntypedStorage will be the only storage class. This should only matter to you if you are using storages directly.  To access UntypedStorage directly, use tensor.untyped_storage() instead of tensor.storage()
  return self.fget.__get__(instance, owner)()
/home/guoyunfei/.conda/envs/llava/lib/python3.10/site-packages/torch/_utils.py:831: UserWarning: TypedStorage is deprecated. It will be removed in the future and UntypedStorage will be the only storage class. This should only matter to you if you are using storages directly.  To access UntypedStorage directly, use tensor.untyped_storage() instead of tensor.storage()
  return self.fget.__get__(instance, owner)()
/home/guoyunfei/.conda/envs/llava/lib/python3.10/site-packages/torch/_utils.py:831: UserWarning: TypedStorage is deprecated. It will be removed in the future and UntypedStorage will be the only storage class. This should only matter to you if you are using storages directly.  To access UntypedStorage directly, use tensor.untyped_storage() instead of tensor.storage()
  return self.fget.__get__(instance, owner)()
/home/guoyunfei/.conda/envs/llava/lib/python3.10/site-packages/torch/_utils.py:831: UserWarning: TypedStorage is deprecated. It will be removed in the future and UntypedStorage will be the only storage class. This should only matter to you if you are using storages directly.  To access UntypedStorage directly, use tensor.untyped_storage() instead of tensor.storage()
  return self.fget.__get__(instance, owner)()
/home/guoyunfei/.conda/envs/llava/lib/python3.10/site-packages/torch/_utils.py:831: UserWarning: TypedStorage is deprecated. It will be removed in the future and UntypedStorage will be the only storage class. This should only matter to you if you are using storages directly.  To access UntypedStorage directly, use tensor.untyped_storage() instead of tensor.storage()
  return self.fget.__get__(instance, owner)()
/home/guoyunfei/.conda/envs/llava/lib/python3.10/site-packages/torch/_utils.py:831: UserWarning: TypedStorage is deprecated. It will be removed in the future and UntypedStorage will be the only storage class. This should only matter to you if you are using storages directly.  To access UntypedStorage directly, use tensor.untyped_storage() instead of tensor.storage()
  return self.fget.__get__(instance, owner)()
/home/guoyunfei/.conda/envs/llava/lib/python3.10/site-packages/torch/_utils.py:831: UserWarning: TypedStorage is deprecated. It will be removed in the future and UntypedStorage will be the only storage class. This should only matter to you if you are using storages directly.  To access UntypedStorage directly, use tensor.untyped_storage() instead of tensor.storage()
  return self.fget.__get__(instance, owner)()
Loading checkpoint shards: 100%|████████████████████████████████████████████████████████████████████████████████| 4/4 [00:19<00:00,  4.77s/it]
Loading checkpoint shards: 100%|████████████████████████████████████████████████████████████████████████████████| 4/4 [00:19<00:00,  4.97s/it]
Loading checkpoint shards: 100%|████████████████████████████████████████████████████████████████████████████████| 4/4 [00:20<00:00,  5.10s/it]
Loading checkpoint shards: 100%|████████████████████████████████████████████████████████████████████████████████| 4/4 [00:20<00:00,  5.12s/it]
Loading checkpoint shards: 100%|████████████████████████████████████████████████████████████████████████████████| 4/4 [00:20<00:00,  5.13s/it]
Loading checkpoint shards: 100%|████████████████████████████████████████████████████████████████████████████████| 4/4 [00:20<00:00,  5.03s/it]
Loading checkpoint shards: 100%|████████████████████████████████████████████████████████████████████████████████| 4/4 [00:20<00:00,  5.17s/it]
Loading checkpoint shards: 100%|████████████████████████████████████████████████████████████████████████████████| 4/4 [00:20<00:00,  5.01s/it]
openai/clip-vit-large-patch14-336 is already loaded, `load_model` called again, skipping.
openai/clip-vit-large-patch14-336 is already loaded, `load_model` called again, skipping.
openai/clip-vit-large-patch14-336 is already loaded, `load_model` called again, skipping.
openai/clip-vit-large-patch14-336 is already loaded, `load_model` called again, skipping.
openai/clip-vit-large-patch14-336 is already loaded, `load_model` called again, skipping.
openai/clip-vit-large-patch14-336 is already loaded, `load_model` called again, skipping.
openai/clip-vit-large-patch14-336 is already loaded, `load_model` called again, skipping.
Formatting inputs...Skip in lazy mode
openai/clip-vit-large-patch14-336 is already loaded, `load_model` called again, skipping.
wandb: Currently logged in as: james20201124 (james20201124-temple-university). Use `wandb login --relogin` to force relogin
wandb: Tracking run with wandb version 0.17.5
wandb: Run data is saved locally in /home/guoyunfei/projects/LLaVA-main/llava/wandb/run-20240816_161631-m3mtmisw
wandb: Run `wandb offline` to turn off syncing.
wandb: Syncing run misunderstood-cloud-37
wandb: ⭐️ View project at https://wandb.ai/james20201124-temple-university/huggingface
wandb: 🚀 View run at https://wandb.ai/james20201124-temple-university/huggingface/runs/m3mtmisw
  0%|                                                                                                                 | 0/443 [00:00<?, ?it/s]Traceback (most recent call last):
  File "/home/guoyunfei/projects/LLaVA-main/llava/train/train_mem.py", line 4, in <module>
    train(attn_implementation="flash_attention_2")
  File "/home/guoyunfei/projects/LLaVA-main/llava/train/train.py", line 978, in train
    trainer.train()
  File "/home/guoyunfei/.conda/envs/llava/lib/python3.10/site-packages/transformers/trainer.py", line 1539, in train
    return inner_training_loop(
  File "/home/guoyunfei/.conda/envs/llava/lib/python3.10/site-packages/transformers/trainer.py", line 1836, in _inner_training_loop
    for step, inputs in enumerate(epoch_iterator):
  File "/home/guoyunfei/.conda/envs/llava/lib/python3.10/site-packages/accelerate/data_loader.py", line 384, in __iter__
    current_batch = next(dataloader_iter)
  File "/home/guoyunfei/.conda/envs/llava/lib/python3.10/site-packages/torch/utils/data/dataloader.py", line 630, in __next__
    data = self._next_data()
  File "/home/guoyunfei/.conda/envs/llava/lib/python3.10/site-packages/torch/utils/data/dataloader.py", line 1345, in _next_data
    return self._process_data(data)
  File "/home/guoyunfei/.conda/envs/llava/lib/python3.10/site-packages/torch/utils/data/dataloader.py", line 1371, in _process_data
    data.reraise()
  File "/home/guoyunfei/.conda/envs/llava/lib/python3.10/site-packages/torch/_utils.py", line 694, in reraise
    raise exception
FileNotFoundError: Caught FileNotFoundError in DataLoader worker process 0.
Original Traceback (most recent call last):
  File "/home/guoyunfei/.conda/envs/llava/lib/python3.10/site-packages/torch/utils/data/_utils/worker.py", line 308, in _worker_loop
    data = fetcher.fetch(index)
  File "/home/guoyunfei/.conda/envs/llava/lib/python3.10/site-packages/torch/utils/data/_utils/fetch.py", line 51, in fetch
    data = [self.dataset[idx] for idx in possibly_batched_index]
  File "/home/guoyunfei/.conda/envs/llava/lib/python3.10/site-packages/torch/utils/data/_utils/fetch.py", line 51, in <listcomp>
    data = [self.dataset[idx] for idx in possibly_batched_index]
  File "/home/guoyunfei/projects/LLaVA-main/llava/train/train.py", line 708, in __getitem__
    image = Image.open(os.path.join(image_folder, image_file)).convert('RGB')
  File "/home/guoyunfei/.conda/envs/llava/lib/python3.10/site-packages/PIL/Image.py", line 3431, in open
    fp = builtins.open(filename, "rb")
FileNotFoundError: [Errno 2] No such file or directory: '/data0/GYF/data/llava-med/images/35686263_FIG1.jpg'

Traceback (most recent call last):
  File "/home/guoyunfei/projects/LLaVA-main/llava/train/train_mem.py", line 4, in <module>
    train(attn_implementation="flash_attention_2")
  File "/home/guoyunfei/projects/LLaVA-main/llava/train/train.py", line 978, in train
    trainer.train()
  File "/home/guoyunfei/.conda/envs/llava/lib/python3.10/site-packages/transformers/trainer.py", line 1539, in train
    return inner_training_loop(
  File "/home/guoyunfei/.conda/envs/llava/lib/python3.10/site-packages/transformers/trainer.py", line 1836, in _inner_training_loop
    for step, inputs in enumerate(epoch_iterator):
  File "/home/guoyunfei/.conda/envs/llava/lib/python3.10/site-packages/accelerate/data_loader.py", line 384, in __iter__
    current_batch = next(dataloader_iter)
  File "/home/guoyunfei/.conda/envs/llava/lib/python3.10/site-packages/torch/utils/data/dataloader.py", line 630, in __next__
    data = self._next_data()
  File "/home/guoyunfei/.conda/envs/llava/lib/python3.10/site-packages/torch/utils/data/dataloader.py", line 1345, in _next_data
    return self._process_data(data)
  File "/home/guoyunfei/.conda/envs/llava/lib/python3.10/site-packages/torch/utils/data/dataloader.py", line 1371, in _process_data
    data.reraise()
  File "/home/guoyunfei/.conda/envs/llava/lib/python3.10/site-packages/torch/_utils.py", line 694, in reraise
    raise exception
FileNotFoundError: Caught FileNotFoundError in DataLoader worker process 0.
Original Traceback (most recent call last):
  File "/home/guoyunfei/.conda/envs/llava/lib/python3.10/site-packages/torch/utils/data/_utils/worker.py", line 308, in _worker_loop
    data = fetcher.fetch(index)
  File "/home/guoyunfei/.conda/envs/llava/lib/python3.10/site-packages/torch/utils/data/_utils/fetch.py", line 51, in fetch
    data = [self.dataset[idx] for idx in possibly_batched_index]
  File "/home/guoyunfei/.conda/envs/llava/lib/python3.10/site-packages/torch/utils/data/_utils/fetch.py", line 51, in <listcomp>
    data = [self.dataset[idx] for idx in possibly_batched_index]
  File "/home/guoyunfei/projects/LLaVA-main/llava/train/train.py", line 708, in __getitem__
    image = Image.open(os.path.join(image_folder, image_file)).convert('RGB')
  File "/home/guoyunfei/.conda/envs/llava/lib/python3.10/site-packages/PIL/Image.py", line 3431, in open
    fp = builtins.open(filename, "rb")
FileNotFoundError: [Errno 2] No such file or directory: '/data0/GYF/data/llava-med/images/29531232_Fig1.jpg'

ERROR:root:Assertion error for source: [{'from': 'human', 'value': '<image>\nWhat are the different staining techniques used in the image?'}, {'from': 'gpt', 'value': "The image shows three different staining techniques used for the pathological analysis of the kidneys. These techniques are Hematoxylin and Eosin (H&E) staining, Periodic Acid-Schiff (PAS) staining, and Masson's trichrome staining."}, {'from': 'human', 'value': 'What do the arrows represent in the H&E staining?'}, {'from': 'gpt', 'value': 'In the H&E staining, the arrows represent renal tubular necrosis, which is a type of kidney damage involving the death of tubular epithelial cells, the cells that line the renal tubules.'}, {'from': 'human', 'value': 'What do the arrows represent in the PAS staining?'}, {'from': 'gpt', 'value': 'In the PAS staining, the arrows represent mesangial expansion. Mesangial expansion refers to the increase in the size or number of mesangial cells, which are specialized cells in the kidney that help support the glomerular capillaries and regulate blood flow in the glomerulus. Mesangial expansion can be a sign of kidney disease or damage.'}]. Error: 
Traceback (most recent call last):
  File "/home/guoyunfei/projects/LLaVA-main/llava/train/train_mem.py", line 4, in <module>
    train(attn_implementation="flash_attention_2")
  File "/home/guoyunfei/projects/LLaVA-main/llava/train/train.py", line 978, in train
    trainer.train()
  File "/home/guoyunfei/.conda/envs/llava/lib/python3.10/site-packages/transformers/trainer.py", line 1539, in train
    return inner_training_loop(
  File "/home/guoyunfei/.conda/envs/llava/lib/python3.10/site-packages/transformers/trainer.py", line 1836, in _inner_training_loop
    for step, inputs in enumerate(epoch_iterator):
  File "/home/guoyunfei/.conda/envs/llava/lib/python3.10/site-packages/accelerate/data_loader.py", line 384, in __iter__
    current_batch = next(dataloader_iter)
  File "/home/guoyunfei/.conda/envs/llava/lib/python3.10/site-packages/torch/utils/data/dataloader.py", line 630, in __next__
    data = self._next_data()
  File "/home/guoyunfei/.conda/envs/llava/lib/python3.10/site-packages/torch/utils/data/dataloader.py", line 1345, in _next_data
    return self._process_data(data)
  File "/home/guoyunfei/.conda/envs/llava/lib/python3.10/site-packages/torch/utils/data/dataloader.py", line 1371, in _process_data
Traceback (most recent call last):
  File "/home/guoyunfei/projects/LLaVA-main/llava/train/train_mem.py", line 4, in <module>
    data.reraise()
  File "/home/guoyunfei/.conda/envs/llava/lib/python3.10/site-packages/torch/_utils.py", line 694, in reraise
    raise exception    
train(attn_implementation="flash_attention_2")
FileNotFoundError: Caught FileNotFoundError in DataLoader worker process 0.
Original Traceback (most recent call last):
  File "/home/guoyunfei/.conda/envs/llava/lib/python3.10/site-packages/torch/utils/data/_utils/worker.py", line 308, in _worker_loop
    data = fetcher.fetch(index)
  File "/home/guoyunfei/.conda/envs/llava/lib/python3.10/site-packages/torch/utils/data/_utils/fetch.py", line 51, in fetch
    data = [self.dataset[idx] for idx in possibly_batched_index]
  File "/home/guoyunfei/.conda/envs/llava/lib/python3.10/site-packages/torch/utils/data/_utils/fetch.py", line 51, in <listcomp>
    data = [self.dataset[idx] for idx in possibly_batched_index]
  File "/home/guoyunfei/projects/LLaVA-main/llava/train/train.py", line 708, in __getitem__
    image = Image.open(os.path.join(image_folder, image_file)).convert('RGB')
  File "/home/guoyunfei/.conda/envs/llava/lib/python3.10/site-packages/PIL/Image.py", line 3431, in open
    fp = builtins.open(filename, "rb")
FileNotFoundError: [Errno 2] No such file or directory: '/data0/GYF/data/llava-med/images/32548579_fig1-2632010X20906166.jpg'
  File "/home/guoyunfei/projects/LLaVA-main/llava/train/train.py", line 978, in train

    trainer.train()
  File "/home/guoyunfei/.conda/envs/llava/lib/python3.10/site-packages/transformers/trainer.py", line 1539, in train
    return inner_training_loop(
  File "/home/guoyunfei/.conda/envs/llava/lib/python3.10/site-packages/transformers/trainer.py", line 1836, in _inner_training_loop
    for step, inputs in enumerate(epoch_iterator):
  File "/home/guoyunfei/.conda/envs/llava/lib/python3.10/site-packages/accelerate/data_loader.py", line 384, in __iter__
    current_batch = next(dataloader_iter)
  File "/home/guoyunfei/.conda/envs/llava/lib/python3.10/site-packages/torch/utils/data/dataloader.py", line 630, in __next__
    data = self._next_data()
  File "/home/guoyunfei/.conda/envs/llava/lib/python3.10/site-packages/torch/utils/data/dataloader.py", line 1345, in _next_data
    return self._process_data(data)
  File "/home/guoyunfei/.conda/envs/llava/lib/python3.10/site-packages/torch/utils/data/dataloader.py", line 1371, in _process_data
    data.reraise()
  File "/home/guoyunfei/.conda/envs/llava/lib/python3.10/site-packages/torch/_utils.py", line 694, in reraise
    raise exception
FileNotFoundError: Caught FileNotFoundError in DataLoader worker process 0.
Original Traceback (most recent call last):
  File "/home/guoyunfei/.conda/envs/llava/lib/python3.10/site-packages/torch/utils/data/_utils/worker.py", line 308, in _worker_loop
    data = fetcher.fetch(index)
  File "/home/guoyunfei/.conda/envs/llava/lib/python3.10/site-packages/torch/utils/data/_utils/fetch.py", line 51, in fetch
    data = [self.dataset[idx] for idx in possibly_batched_index]
  File "/home/guoyunfei/.conda/envs/llava/lib/python3.10/site-packages/torch/utils/data/_utils/fetch.py", line 51, in <listcomp>
    data = [self.dataset[idx] for idx in possibly_batched_index]
  File "/home/guoyunfei/projects/LLaVA-main/llava/train/train.py", line 708, in __getitem__
    image = Image.open(os.path.join(image_folder, image_file)).convert('RGB')
  File "/home/guoyunfei/.conda/envs/llava/lib/python3.10/site-packages/PIL/Image.py", line 3431, in open
    fp = builtins.open(filename, "rb")
FileNotFoundError: [Errno 2] No such file or directory: '/data0/GYF/data/llava-med/images/29306264_f2-ceem-16-177.jpg'

Traceback (most recent call last):
  File "/home/guoyunfei/projects/LLaVA-main/llava/train/train_mem.py", line 4, in <module>
    train(attn_implementation="flash_attention_2")
  File "/home/guoyunfei/projects/LLaVA-main/llava/train/train.py", line 978, in train
    trainer.train()
  File "/home/guoyunfei/.conda/envs/llava/lib/python3.10/site-packages/transformers/trainer.py", line 1539, in train
    return inner_training_loop(
  File "/home/guoyunfei/.conda/envs/llava/lib/python3.10/site-packages/transformers/trainer.py", line 1836, in _inner_training_loop
    for step, inputs in enumerate(epoch_iterator):
  File "/home/guoyunfei/.conda/envs/llava/lib/python3.10/site-packages/accelerate/data_loader.py", line 384, in __iter__
ERROR:root:Assertion error for source: [{'from': 'human', 'value': '<image>\nWhat is the purpose of the chest X-ray?'}, {'from': 'gpt', 'value': 'The purpose of the chest X-ray in this case is to verify the placement of a peripherally inserted central catheter (PICC) line.'}, {'from': 'human', 'value': 'What is the foreign body found in the image?'}, {'from': 'gpt', 'value': 'The foreign body found in the image is a portion of the plastic sheath covering the stylet, which was used during intubation.'}, {'from': 'human', 'value': "What is the condition of the patient's lungs?"}, {'from': 'gpt', 'value': "The patient's lungs show right middle and right lower lobe atelectasis, which is a partial collapse or incomplete inflation of the lung tissue. Additionally, there is a shifting of the cardiac silhouette to the right. This suggests that there may be some issues with the patient's lung function, and it is important for the medical team to closely monitor the patient's condition and provide appropriate treatment to manage their symptoms and improve their lung function."}]. Error: 
Traceback (most recent call last):
  File "/home/guoyunfei/projects/LLaVA-main/llava/train/train_mem.py", line 4, in <module>
    current_batch = next(dataloader_iter)
    train(attn_implementation="flash_attention_2")  File "/home/guoyunfei/.conda/envs/llava/lib/python3.10/site-packages/torch/utils/data/dataloader.py", line 630, in __next__

  File "/home/guoyunfei/projects/LLaVA-main/llava/train/train.py", line 978, in train
    data = self._next_data()
  File "/home/guoyunfei/.conda/envs/llava/lib/python3.10/site-packages/torch/utils/data/dataloader.py", line 1345, in _next_data
    trainer.train()
  File "/home/guoyunfei/.conda/envs/llava/lib/python3.10/site-packages/transformers/trainer.py", line 1539, in train
    return self._process_data(data)
  File "/home/guoyunfei/.conda/envs/llava/lib/python3.10/site-packages/torch/utils/data/dataloader.py", line 1371, in _process_data
    return inner_training_loop(
  File "/home/guoyunfei/.conda/envs/llava/lib/python3.10/site-packages/transformers/trainer.py", line 1836, in _inner_training_loop
    data.reraise()
  File "/home/guoyunfei/.conda/envs/llava/lib/python3.10/site-packages/torch/_utils.py", line 694, in reraise
    raise exception
FileNotFoundError: Caught FileNotFoundError in DataLoader worker process 0.
Original Traceback (most recent call last):
  File "/home/guoyunfei/.conda/envs/llava/lib/python3.10/site-packages/torch/utils/data/_utils/worker.py", line 308, in _worker_loop
    data = fetcher.fetch(index)
  File "/home/guoyunfei/.conda/envs/llava/lib/python3.10/site-packages/torch/utils/data/_utils/fetch.py", line 51, in fetch
    data = [self.dataset[idx] for idx in possibly_batched_index]
  File "/home/guoyunfei/.conda/envs/llava/lib/python3.10/site-packages/torch/utils/data/_utils/fetch.py", line 51, in <listcomp>
    data = [self.dataset[idx] for idx in possibly_batched_index]
  File "/home/guoyunfei/projects/LLaVA-main/llava/train/train.py", line 708, in __getitem__
    image = Image.open(os.path.join(image_folder, image_file)).convert('RGB')
  File "/home/guoyunfei/.conda/envs/llava/lib/python3.10/site-packages/PIL/Image.py", line 3431, in open
    fp = builtins.open(filename, "rb")
FileNotFoundError: [Errno 2] No such file or directory: '/data0/GYF/data/llava-med/images/34337340_jsp21167-fig-0017.jpg'

    for step, inputs in enumerate(epoch_iterator):
  File "/home/guoyunfei/.conda/envs/llava/lib/python3.10/site-packages/accelerate/data_loader.py", line 384, in __iter__
    current_batch = next(dataloader_iter)
  File "/home/guoyunfei/.conda/envs/llava/lib/python3.10/site-packages/torch/utils/data/dataloader.py", line 630, in __next__
    data = self._next_data()
  File "/home/guoyunfei/.conda/envs/llava/lib/python3.10/site-packages/torch/utils/data/dataloader.py", line 1345, in _next_data
    return self._process_data(data)
  File "/home/guoyunfei/.conda/envs/llava/lib/python3.10/site-packages/torch/utils/data/dataloader.py", line 1371, in _process_data
    data.reraise()
  File "/home/guoyunfei/.conda/envs/llava/lib/python3.10/site-packages/torch/_utils.py", line 694, in reraise
    raise exception
FileNotFoundError: Caught FileNotFoundError in DataLoader worker process 0.
Original Traceback (most recent call last):
  File "/home/guoyunfei/.conda/envs/llava/lib/python3.10/site-packages/torch/utils/data/_utils/worker.py", line 308, in _worker_loop
    data = fetcher.fetch(index)
  File "/home/guoyunfei/.conda/envs/llava/lib/python3.10/site-packages/torch/utils/data/_utils/fetch.py", line 51, in fetch
    data = [self.dataset[idx] for idx in possibly_batched_index]
  File "/home/guoyunfei/.conda/envs/llava/lib/python3.10/site-packages/torch/utils/data/_utils/fetch.py", line 51, in <listcomp>
    data = [self.dataset[idx] for idx in possibly_batched_index]
  File "/home/guoyunfei/projects/LLaVA-main/llava/train/train.py", line 708, in __getitem__
    image = Image.open(os.path.join(image_folder, image_file)).convert('RGB')
  File "/home/guoyunfei/.conda/envs/llava/lib/python3.10/site-packages/PIL/Image.py", line 3431, in open
    fp = builtins.open(filename, "rb")
FileNotFoundError: [Errno 2] No such file or directory: '/data0/GYF/data/llava-med/images/24648680_F3.jpg'

Traceback (most recent call last):
  File "/home/guoyunfei/projects/LLaVA-main/llava/train/train_mem.py", line 4, in <module>
    train(attn_implementation="flash_attention_2")
  File "/home/guoyunfei/projects/LLaVA-main/llava/train/train.py", line 978, in train
    trainer.train()
  File "/home/guoyunfei/.conda/envs/llava/lib/python3.10/site-packages/transformers/trainer.py", line 1539, in train
    return inner_training_loop(
  File "/home/guoyunfei/.conda/envs/llava/lib/python3.10/site-packages/transformers/trainer.py", line 1836, in _inner_training_loop
    for step, inputs in enumerate(epoch_iterator):
  File "/home/guoyunfei/.conda/envs/llava/lib/python3.10/site-packages/accelerate/data_loader.py", line 384, in __iter__
    current_batch = next(dataloader_iter)
  File "/home/guoyunfei/.conda/envs/llava/lib/python3.10/site-packages/torch/utils/data/dataloader.py", line 630, in __next__
    data = self._next_data()
  File "/home/guoyunfei/.conda/envs/llava/lib/python3.10/site-packages/torch/utils/data/dataloader.py", line 1345, in _next_data
    return self._process_data(data)
  File "/home/guoyunfei/.conda/envs/llava/lib/python3.10/site-packages/torch/utils/data/dataloader.py", line 1371, in _process_data
    data.reraise()
  File "/home/guoyunfei/.conda/envs/llava/lib/python3.10/site-packages/torch/_utils.py", line 694, in reraise
    raise exception
FileNotFoundError: Caught FileNotFoundError in DataLoader worker process 0.
Original Traceback (most recent call last):
  File "/home/guoyunfei/.conda/envs/llava/lib/python3.10/site-packages/torch/utils/data/_utils/worker.py", line 308, in _worker_loop
    data = fetcher.fetch(index)
  File "/home/guoyunfei/.conda/envs/llava/lib/python3.10/site-packages/torch/utils/data/_utils/fetch.py", line 51, in fetch
    data = [self.dataset[idx] for idx in possibly_batched_index]
  File "/home/guoyunfei/.conda/envs/llava/lib/python3.10/site-packages/torch/utils/data/_utils/fetch.py", line 51, in <listcomp>
    data = [self.dataset[idx] for idx in possibly_batched_index]
  File "/home/guoyunfei/projects/LLaVA-main/llava/train/train.py", line 708, in __getitem__
    image = Image.open(os.path.join(image_folder, image_file)).convert('RGB')
  File "/home/guoyunfei/.conda/envs/llava/lib/python3.10/site-packages/PIL/Image.py", line 3431, in open
    fp = builtins.open(filename, "rb")
FileNotFoundError: [Errno 2] No such file or directory: '/data0/GYF/data/llava-med/images/34926682_fig10.jpg'

ERROR:root:Assertion error for source: [{'from': 'human', 'value': '<image>\nWhat organ is shown in the image?'}, {'from': 'gpt', 'value': 'The image shows the spleen, which is an organ in the abdominal cavity.'}, {'from': 'human', 'value': 'What is the arrow pointing to?'}, {'from': 'gpt', 'value': 'The arrow in the CT scan is pointing to a splenic cyst, which is an abnormal fluid-filled sac within the spleen.'}, {'from': 'human', 'value': 'Is there any involvement of other organs?'}, {'from': 'gpt', 'value': 'There is no involvement of the liver, kidney, or chest in the ct scan. the cyst appears to be localized to the upper pole of the spleen.'}]. Error: 
Traceback (most recent call last):
  File "/home/guoyunfei/projects/LLaVA-main/llava/train/train_mem.py", line 4, in <module>
    train(attn_implementation="flash_attention_2")
  File "/home/guoyunfei/projects/LLaVA-main/llava/train/train.py", line 978, in train
    trainer.train()
  File "/home/guoyunfei/.conda/envs/llava/lib/python3.10/site-packages/transformers/trainer.py", line 1539, in train
    return inner_training_loop(
  File "/home/guoyunfei/.conda/envs/llava/lib/python3.10/site-packages/transformers/trainer.py", line 1836, in _inner_training_loop
    for step, inputs in enumerate(epoch_iterator):
  File "/home/guoyunfei/.conda/envs/llava/lib/python3.10/site-packages/accelerate/data_loader.py", line 384, in __iter__
    current_batch = next(dataloader_iter)
  File "/home/guoyunfei/.conda/envs/llava/lib/python3.10/site-packages/torch/utils/data/dataloader.py", line 630, in __next__
    data = self._next_data()
  File "/home/guoyunfei/.conda/envs/llava/lib/python3.10/site-packages/torch/utils/data/dataloader.py", line 1345, in _next_data
    return self._process_data(data)
  File "/home/guoyunfei/.conda/envs/llava/lib/python3.10/site-packages/torch/utils/data/dataloader.py", line 1371, in _process_data
    data.reraise()
  File "/home/guoyunfei/.conda/envs/llava/lib/python3.10/site-packages/torch/_utils.py", line 694, in reraise
    raise exception
IndexError: Caught IndexError in DataLoader worker process 0.
Original Traceback (most recent call last):
  File "/home/guoyunfei/.conda/envs/llava/lib/python3.10/site-packages/torch/utils/data/_utils/worker.py", line 308, in _worker_loop
    data = fetcher.fetch(index)
  File "/home/guoyunfei/.conda/envs/llava/lib/python3.10/site-packages/torch/utils/data/_utils/fetch.py", line 51, in fetch
    data = [self.dataset[idx] for idx in possibly_batched_index]
  File "/home/guoyunfei/.conda/envs/llava/lib/python3.10/site-packages/torch/utils/data/_utils/fetch.py", line 51, in <listcomp>
    data = [self.dataset[idx] for idx in possibly_batched_index]
  File "/home/guoyunfei/projects/LLaVA-main/llava/train/train.py", line 736, in __getitem__
    data_dict = dict(input_ids=data_dict["input_ids"][0],
IndexError: list index out of range

ERROR:root:Assertion error for source: [{'from': 'human', 'value': '<image>\nWhat is the purpose of the workflow?'}, {'from': 'gpt', 'value': "The purpose of the workflow is to provide a visual representation of the steps and processes involved in the current study. It helps to illustrate the sequence of events, methods, and analyses used to achieve the study's objectives. By presenting the workflow, it becomes easier for readers to understand the overall structure and progression of the research."}, {'from': 'human', 'value': 'What are some of the methods or analyses mentioned in the workflow?'}, {'from': 'gpt', 'value': 'Some of the methods and analyses mentioned in the workflow include computed tomography (CT), intraclass correlation coefficient (ICC), least absolute shrinkage and selection operator (LASSO), receiver operating characteristic (ROC), and area under the ROC curve (AUC). These methods and analyses are used to process, evaluate, and interpret the data collected during the study.'}, {'from': 'human', 'value': 'What is the role of the ROC curve in this workflow?'}, {'from': 'gpt', 'value': 'The role of the ROC curve in this workflow is to assess the performance of a diagnostic or predictive model. The ROC curve plots the true positive rate (sensitivity) against the false positive rate (1-specificity) for different threshold values. The area under the ROC curve (AUC) is a measure of the overall performance of the model, with a value of 1 indicating perfect discrimination and a value of 0.5 indicating no better than random chance. In the context of this study, the ROC curve is used to evaluate the accuracy and effectiveness of the model or method being tested.'}]. Error: 
ERROR:root:Assertion error for source: [{'from': 'human', 'value': '<image>\nWhat is the arrow pointing to?'}, {'from': 'gpt', 'value': 'The arrow in the image is pointing to the anomalous umbilical vessels that are originating from the xiphoid process.'}, {'from': 'human', 'value': 'What is the xiphoid process?'}, {'from': 'gpt', 'value': 'The xiphoid process is a small, cartilaginous extension at the lower end of the sternum, which is the breastbone in the center of the chest. It is a thin, elongated structure that projects downward and is made of cartilage in early life but may ossify (turn into bone) as a person ages. The xiphoid process serves as an attachment point for several muscles and ligaments, including the diaphragm and the rectus abdominis muscles.'}, {'from': 'human', 'value': 'What is unusual about the umbilical vessels in this image?'}, {'from': 'gpt', 'value': 'The unusual feature of the umbilical vessels in this image is that they are originating from the xiphoid process, which is not the typical location for umbilical vessels. Normally, umbilical vessels connect the fetus to the placenta in the uterus and are not associated with the xiphoid process. This anomaly is a rare occurrence and may require further evaluation and management by healthcare professionals.'}]. Error: 
ERROR:root:Assertion error for source: [{'from': 'human', 'value': '<image>\nWhat is the image showing?'}, {'from': 'gpt', 'value': 'The image is a chest X-ray of a patient, which is a type of radiographic imaging used to visualize the structures within the chest, including the lungs, heart, and bones of the chest and spine.'}, {'from': 'human', 'value': 'What are the arrows pointing to?'}, {'from': 'gpt', 'value': 'The arrows in the chest X-ray are pointing to areas of infiltration in the bilateral low zones of the lungs. Infiltration refers to the presence of abnormal substances or cells within the lung tissue, which can be caused by various conditions such as infection, inflammation, or other lung diseases.'}, {'from': 'human', 'value': 'What does the infiltration indicate?'}, {'from': 'gpt', 'value': 'Infiltration in the lungs can indicate a variety of conditions, such as pneumonia, bronchitis, or other lung diseases. It can be caused by the accumulation of fluid, cells, or other substances within the lung tissue. The presence of infiltration in the bilateral low zones of the lungs suggests that there may be an underlying issue affecting both lungs. Further evaluation and clinical correlation are needed to determine the cause and significance of these findings. It is important to consult a healthcare professional for a thorough assessment and proper diagnosis.'}]. Error: 
ERROR:root:Assertion error for source: [{'from': 'human', 'value': '<image>\nWhat is the age of the patient?'}, {'from': 'gpt', 'value': 'The patient is 11 years old.'}, {'from': 'human', 'value': 'What type of tumor did the patient have?'}, {'from': 'gpt', 'value': 'The patient had an osteosarcoma, which is a type of bone cancer. In this case, it was located in the proximal tibia.'}, {'from': 'human', 'value': 'What type of resection was performed?'}, {'from': 'gpt', 'value': 'A resection of the tumor was performed, which included the removal of the epiphysis. The margin was classified as R0, indicating that the resection was done with adequate safe margins and no microscopic or macroscopic residual disease was detected.'}]. Error: 
[2024-08-16 16:16:47,385] [INFO] [launch.py:315:sigkill_handler] Killing subprocess 1232486
[2024-08-16 16:16:48,065] [INFO] [launch.py:315:sigkill_handler] Killing subprocess 1232487
[2024-08-16 16:16:48,065] [INFO] [launch.py:315:sigkill_handler] Killing subprocess 1232488
[2024-08-16 16:16:48,103] [INFO] [launch.py:315:sigkill_handler] Killing subprocess 1232489
[2024-08-16 16:16:48,140] [INFO] [launch.py:315:sigkill_handler] Killing subprocess 1232490
[2024-08-16 16:16:48,176] [INFO] [launch.py:315:sigkill_handler] Killing subprocess 1232491
[2024-08-16 16:16:48,209] [INFO] [launch.py:315:sigkill_handler] Killing subprocess 1232492
[2024-08-16 16:16:48,237] [INFO] [launch.py:315:sigkill_handler] Killing subprocess 1232493
[2024-08-16 16:16:48,263] [ERROR] [launch.py:321:sigkill_handler] ['/home/guoyunfei/.conda/envs/llava/bin/python', '-u', '/home/guoyunfei/projects/LLaVA-main/llava/train/train_mem.py', '--local_rank=7', '--deepspeed', '/home/guoyunfei/projects/LLaVA-main/scripts/zero2.json', '--model_name_or_path', '/data0/GYF/offline_model/liuhaotian/llava-v1.6-mistral-7b', '--version', 'plain', '--data_path', '/data0/GYF/data/llava-med/data/Instruction-Tuning/llava_med_instruct_60k_inline_mention2024081602.json', '--image_folder', '/data0/GYF/data/llava-med/images', '--vision_tower', '/data0/GYF/offline_model/openai/clip-vit-large-patch14', '--pretrain_mm_mlp_adapter', './checkpoints/llava-v1.6-7b-13GB-pretrain/mm_projector.bin', '--mm_vision_select_layer', '-2', '--mm_use_im_start_end', 'False', '--mm_use_im_patch_token', 'False', '--bf16', 'True', '--output_dir', './checkpoints/llava-v1.6-7b_plain-finetune', '--num_train_epochs', '1', '--per_device_train_batch_size', '16', '--per_device_eval_batch_size', '4', '--gradient_accumulation_steps', '1', '--evaluation_strategy', 'no', '--save_strategy', 'steps', '--save_steps', '50000', '--save_total_limit', '1', '--learning_rate', '2e-5', '--weight_decay', '0.', '--warmup_ratio', '0.03', '--lr_scheduler_type', 'cosine', '--logging_steps', '1', '--tf32', 'True', '--model_max_length', '2048', '--gradient_checkpointing', 'True', '--dataloader_num_workers', '4', '--lazy_preprocess', 'True', '--report_to', 'wandb'] exits with return code = 1

